Traceback (most recent call last):
  File "/home/codespace/.local/lib/python3.12/site-packages/jupyter_core/utils/__init__.py", line 154, in wrapped
    asyncio.get_running_loop()
RuntimeError: no running event loop

During handling of the above exception, another exception occurred:

Traceback (most recent call last):
  File "/usr/local/python/3.12.1/lib/python3.12/site-packages/jupyter_cache/executors/utils.py", line 58, in single_nb_execution
    executenb(
  File "/home/codespace/.local/lib/python3.12/site-packages/nbclient/client.py", line 1319, in execute
    return NotebookClient(nb=nb, resources=resources, km=km, **kwargs).execute()
           ^^^^^^^^^^^^^^^^^^^^^^^^^^^^^^^^^^^^^^^^^^^^^^^^^^^^^^^^^^^^^^^^^^^^^
  File "/home/codespace/.local/lib/python3.12/site-packages/jupyter_core/utils/__init__.py", line 158, in wrapped
    return loop.run_until_complete(inner)
           ^^^^^^^^^^^^^^^^^^^^^^^^^^^^^^
  File "/usr/local/python/3.12.1/lib/python3.12/asyncio/base_events.py", line 684, in run_until_complete
    return future.result()
           ^^^^^^^^^^^^^^^
  File "/home/codespace/.local/lib/python3.12/site-packages/nbclient/client.py", line 709, in async_execute
    await self.async_execute_cell(
  File "/home/codespace/.local/lib/python3.12/site-packages/nbclient/client.py", line 1062, in async_execute_cell
    await self._check_raise_for_error(cell, cell_index, exec_reply)
  File "/home/codespace/.local/lib/python3.12/site-packages/nbclient/client.py", line 918, in _check_raise_for_error
    raise CellExecutionError.from_cell_and_msg(cell, exec_reply_content)
nbclient.exceptions.CellExecutionError: An error occurred while executing the following cell:
------------------
import pandas as pd

# contoh load dataset dari file csv
df = pd.read_csv("HasilTransform.csv")

from pycaret.anomaly import *

# setup environment
exp = setup(data=df, session_id=123)
model = create_model('iforest')

------------------


[31m---------------------------------------------------------------------------[39m
[31mRuntimeError[39m                              Traceback (most recent call last)
[36mCell[39m[36m [39m[32mIn[2][39m[32m, line 6[39m
[32m      3[39m [38;5;66;03m# contoh load dataset dari file csv[39;00m
[32m      4[39m df = pd.read_csv([33m"[39m[33mHasilTransform.csv[39m[33m"[39m)
[32m----> [39m[32m6[39m [38;5;28;01mfrom[39;00m[38;5;250m [39m[34;01mpycaret[39;00m[34;01m.[39;00m[34;01manomaly[39;00m[38;5;250m [39m[38;5;28;01mimport[39;00m *
[32m      8[39m [38;5;66;03m# setup environment[39;00m
[32m      9[39m exp = setup(data=df, session_id=[32m123[39m)

[36mFile [39m[32m/usr/local/python/3.12.1/lib/python3.12/site-packages/pycaret/__init__.py:22[39m
[32m     16[39m     [38;5;28;01mraise[39;00m [38;5;167;01mRuntimeError[39;00m(
[32m     17[39m         [33m"[39m[33mPycaret only supports python 3.9, 3.10, 3.11. Your actual Python version: [39m[33m"[39m,
[32m     18[39m         sys.version_info,
[32m     19[39m         [33m"[39m[33mPlease UPGRADE your Python version.[39m[33m"[39m,
[32m     20[39m     )
[32m     21[39m [38;5;28;01melif[39;00m sys.version_info >= ([32m3[39m, [32m12[39m):
[32m---> [39m[32m22[39m     [38;5;28;01mraise[39;00m [38;5;167;01mRuntimeError[39;00m(
[32m     23[39m         [33m"[39m[33mPycaret only supports python 3.9, 3.10, 3.11. Your actual Python version: [39m[33m"[39m,
[32m     24[39m         sys.version_info,
[32m     25[39m         [33m"[39m[33mPlease DOWNGRADE your Python version.[39m[33m"[39m,
[32m     26[39m     )

[31mRuntimeError[39m: ('Pycaret only supports python 3.9, 3.10, 3.11. Your actual Python version: ', sys.version_info(major=3, minor=12, micro=1, releaselevel='final', serial=0), 'Please DOWNGRADE your Python version.')

